<link rel="stylesheet" type="text/css" href="../styles/reset.css" />
<link rel="stylesheet" type="text/css" href="../styles/curricula.css" />
<h1>Excepciones</h1>
<p>
  Las excepciones se utilizan para cambiar el flujo normal de una secuencia de comandos si se produce un error especificado.
</p>
<h1>¿Qué es una excepción?</h1>
<p>
  Con PHP 5 llegó una nueva forma orientada a objetos de tratamiento de errores.

El manejo de excepciones se utiliza para cambiar el flujo normal de la ejecución de código si se produce un error especificado (excepcional) condición. Esta condición se llama una excepción.

Esto es lo que sucede normalmente cuando se activa una excepción:
<ul>
  <li>El estado actual código se guarda</li>
  <li>La ejecución de código va a cambiar a un (a medida) la función de gestión de excepciones predefinido</li>
  <li>Dependiendo de la situación, el controlador puede entonces continuar con la ejecución del estado de código guardado, terminar la ejecución del script o continuar la secuencia de comandos desde un lugar diferente en el código</li>
</ul>
Vamos a mostrar los diferentes métodos de tratamiento de errores:
<ul>
  <li>Uso básico de excepciones</li>
  <li>Creación de un manejador de excepción personalizada</li>
  <li>Múltiples excepciones</li>
  <li>Volver a enviar una excepción</li>
  <li>Configuración de un controlador de excepciones de nivel superior</li>
</ul>
Nota: Las excepciones sólo se deben utilizar con condiciones de error y no se deben utilizar para saltar a otro lugar en el código en un punto especificado.
</p>
<h1>Uso básico de excepciones</h1>
<p>
  Cuando se produce una excepción, el siguiente código no se ejecutará, y PHP intentará encontrar el bloque de adaptación "captura".
Si una excepción no se detecta, un error fatal se emite con un mensaje de "Excepción no detectada".
Vamos a tratar de lanzar una excepción sin la captura de él:

&lt;?php
//create function with an exception
function checkNum($number) {
  if($number>1) {
    throw new Exception("Value must be 1 or below");
  }
  return true;
}

//trigger exception
checkNum(2);
?>

El código anterior obtendrá un error como este:

Fatal error: Uncaught exception 'Exception'
with message 'Value must be 1 or below' in C:\webfolder\test.php:6
Stack trace: #0 C:\webfolder\test.php(12):
checkNum(28) #1 {main} thrown in C:\webfolder\test.php on line 6
</p>
<h1>Try, throw y catch</h1>
<p>
  Para evitar el error en el ejemplo anterior, tenemos que crear el código adecuado para manejar una excepción.

código apropiado excepción debe incluir:

<ol>
  <li>Try - Una función usando una excepción debe estar en un bloque de "try". Si la excepción no se activa, el código continuará con normalidad. Sin embargo, si la excepción desencadena, una excepción es "throw"</li>
  <li>Throw - Esta es la forma en que se activa una excepción. Cada "throw" debe tener al menos una "catch"</li>
  <li>Catch - Un bloque de "catch" recupera una excepción y crea un objeto que contiene la información de excepción</li>
</ol>
Vamos a tratar de desencadenar una excepción con código válido:

&lt;?php
//create function with an exception
function checkNum($number) {
  if($number>1) {
    throw new Exception("Value must be 1 or below");
  }
  return true;
}

//trigger exception in a "try" block
try {
  checkNum(2);
  //If the exception is thrown, this text will not be shown
  echo 'If you see this, the number is 1 or below';
}

//catch exception
catch(Exception $e) {
  echo 'Message: ' .$e->getMessage();
}
?>

El código anterior obtendrá un error como este:

Message: Value must be 1 or below
</p>
<h1>Ejemplo explicado</h1>
<p>
  El código anterior produce una excepción y lo atrapa:
  <ol>
    <li>Se crea la función checkNum (). Comprueba si un número es mayor que 1. Si lo es, se produce una excepción</li>
    <li>La función checkNum () se llama en un bloque de "try"</li>
    <li>La excepción dentro de la función checkNum () es lanzada</li>
    <li>El bloque de "atrapar" recupera la excepción y crea un objeto ($ e) que contiene la información de excepción</li>
    <li>El mensaje de error de excepción se hizo eco llamando $ e-> getMessage () del objeto de excepción</li>
  </ol>
  Sin embargo, una manera de moverse por la "cada tiro debe tener una captura" regla es fijar un controlador de excepciones de nivel superior para controlar los errores que se deslizan a través.
</p>
<h1>Creación de una excepción personalizada</h1>
<p>
  Para crear un manejador de excepciones personalizado que debe crear una clase especial con funciones que se pueden llamar cuando se produce una excepción en PHP. La clase debe ser una extensión de la clase de excepción.
La clase de excepción personalizada hereda las propiedades de la clase de excepción de PHP y se puede añadir funciones personalizadas a la misma.
Vamos a crear una clase de excepción:

&lt;?php
class customException extends Exception {
  public function errorMessage() {
    //mensaje de error
    $errorMsg = 'Error on line '.$this->getLine().' in '.$this->getFile()
    .': &lt;b>'.$this->getMessage().'&lt;/b> is not a valid E-Mail address';
    return $errorMsg;
  }
}

$email = "someone@example...com";

try {
  //check if
  if(filter_var($email, FILTER_VALIDATE_EMAIL) === FALSE) {
    //Lanza una excepción si el E-mail no es válido
    throw new customException($email);
  }
}

catch (customException $e) {
  //Muestra un mensaje personalizado
  echo $e->errorMessage();
}
?>

La nueva clase es una copia de la clase de excepción de edad, con una adición de la función errorMessage (). Dado que es una copia de la clase de edad, y que hereda las propiedades y métodos de la clase de edad, podemos usar los métodos de la clase de excepción como getLine () y getFile () y getMessage ().
</p>
<h1>Ejemplo explicado</h1>
<p>
  El código anterior produce una excepción y atrapa con una clase de excepción personalizada:
  <ol>
    <li>La clase customException () se crea como una extensión de la clase de excepción de edad. De esta manera se hereda todos los métodos y propiedades de la clase de excepción de edad</li>
    <li>Se crea la función errorMessage (). Esta función devuelve un mensaje de error si una dirección de e-mail no es válida</li>
    <li>La variable $ correo electrónico se establece en una cadena que no es una dirección válida de correo electrónico</li>
    <li>El bloque "tratar" se ejecuta y se produce una excepción ya que la dirección de correo electrónico no es válido</li>
    <li>El bloque de "atrapar" captura la excepción y muestra el mensaje de error</li>
  </ol>
</p>
<h1>Múltiples excepciones</h1>
<p>
  Es posible que una secuencia de comandos para utilizar varias excepciones para comprobar si hay múltiples condiciones.

Es posible utilizar varios bloques if..else, un interruptor, o anidar varias excepciones. Estas excepciones pueden utilizar diferentes clases de excepción y devolver diferentes mensajes de error:

&lt;?php
class customException extends Exception {
  public function errorMessage() {
    //Mensaje de error
    $errorMsg = 'Error on line '.$this->getLine().' in '.$this->getFile()
    .': &lt;b>'.$this->getMessage().'&lt;/b> is not a valid E-Mail address';
    return $errorMsg;
  }
}

$email = "someone@example.com";

try {
  if(filter_var($email, FILTER_VALIDATE_EMAIL) === FALSE) {
    //Lanza una excepción si el E-mail no es válido
    throw new customException($email);
  }
  //checkea por una "muestra" en el E-mail
  if(strpos($email, "example") !== FALSE) {
    throw new Exception("$email is an example e-mail");
  }
}

catch (customException $e) {
  echo $e->errorMessage();
}

catch(Exception $e) {
  echo $e->getMessage();
}
?>
</p>
<h1>Ejemplo explicado</h1>
<p>
  El código anterior comprueba dos condiciones y lanza una excepción si no se cumple alguna de las condiciones:
  <ol>
    <li>La clase customException () se crea como una extensión de la clase de excepción de edad. De esta manera se hereda todos los métodos y propiedades de la clase de excepción de edad</li>
    <li>Se crea la función errorMessage (). Esta función devuelve un mensaje de error si una dirección de e-mail no es válida</li>
    <li>La variable $ correo electrónico se establece en una cadena que es una dirección válida de correo electrónico, sino que contiene la cadena "ejemplo"</li>
    <li>El bloque "tratar" se ejecuta y no una excepción es lanzada en la primera condición</li>
    <li>La segunda condición desencadena una excepción ya que el correo electrónico contiene el "ejemplo" string</li>
    <li>El bloque de "atrapar" captura la excepción y muestra el mensaje de error correcto</li>
  </ol>
  Si la excepción lanzada fuera de la customException clase y no había ninguna captura customException, sólo la captura excepción de base, la excepción sería manejado allí.
</p>
<h1>Re-lanzar excepciones</h1>
<p>
  A veces, cuando se produce una excepción, es posible que desee para manejar la situación de manera diferente a la forma estándar. Es posible lanzar una excepción por segunda vez dentro de un bloque de "captura".
Una secuencia de comandos debe ocultar errores en el sistema de los usuarios. Los errores del sistema pueden ser importantes para el codificador, pero no son de interés para el usuario. Para hacer las cosas más fácil para el usuario puede volver a emitir la excepción con un mensaje fácil de usar:

&lt;?php
class customException extends Exception {
  public function errorMessage() {
    //mensaje de error
    $errorMsg = $this->getMessage().' is not a valid E-Mail address.';
    return $errorMsg;
  }
}

$email = "someone@example.com";

try {
  try {

    if(strpos($email, "example") !== FALSE) {
      //lanza una excepción si el mail no es válido
      throw new Exception($email);
    }
  }
  catch(Exception $e) {
    //relanza una excepción
    throw new customException($email);
  }
}

catch (customException $e) {
  //muestra un mensaje
  echo $e->errorMessage();
}
?>
</p>
<h1>Ejemplo explicado</h1>
<p>
  El código anterior comprueba si la dirección de correo electrónico contiene el "ejemplo" cadena en ella, si lo hace, la excepción es re-lanzado:
  <ol>
    <li>La clase customException () se crea como una extensión de la clase de excepción de edad. De esta manera se hereda todos los métodos y propiedades de la clase de excepción de edad</li>
    <li>Se crea la función errorMessage (). Esta función devuelve un mensaje de error si una dirección de e-mail no es válida</li>
    <li>La variable $ correo electrónico se establece en una cadena que es una dirección válida de correo electrónico, sino que contiene la cadena "ejemplo"</li>
    <li>El bloque "tratar" contiene otro bloque "tratar" de hacer que sea posible volver a emitir la excepción</li>
    <li>La excepción se dispara desde el correo electrónico contiene el "ejemplo" string</li>
    <li>El bloque de "atrapar" captura la excepción y re-lanza un "customException"</li>
    <li>El "customException" se detecta y se muestra un mensaje de error</li>
   </ol>
   Si la excepción no se detecta en su bloque actual "try", se buscará un bloque catch en "niveles más altos".
</p>
<h1>Establecer un handler de excepción de nivel superior</h1>
<p>
  La función set_exception_handler () establece una función definida por el usuario para manejar todas las excepciones no capturadas.

&lt;?php
function myException($exception) {
  echo "<b>Exception:</b> " . $exception->getMessage();
}
set_exception_handler('myException');
throw new Exception('Uncaught Exception occurred');
?>

La salida del código anterior debería ser algo como esto:

Exception: Uncaught Exception occurred

En el código anterior no había bloque de "captura". En cambio, el gestor de excepciones de nivel superior activa. Esta función debe ser utilizado para capturar las excepciones no capturadas.
</p>
<h1>Reglas para excepciones</h1>
<p>
  <ul>
    <li>Código puede estar rodeado en un bloque try, para ayudar a capturar a los posibles excepciones</li>
    <li>Cada bloque try o throw deben tener al menos un bloque catch correspondiente</li>
    <li>bloques de capturas múltiples se pueden utilizar para capturar diferentes clases de excepciones</li>
    <li>Las excepciones pueden ser lanzadas (o re-lanzados) en un bloque de captura dentro de un bloque try</li>
  </ul>
  Una simple regla: Si tiras algo, usted tiene que atraparla.
</p>
